Workbook

Sheet Results Summary
B2: Overall Accuracy | I2: In-progress overall
C3: Accurate 5% | D3: Acceptable (10%) | E3: Not-Acceptable (>10%) | F3: Total | J3: Accurate 5% | K3: Acceptable (10%) | L3: Not-Acceptable (>10%)
B4: Baseline | C4: =COUNTIF(Baseline!$F:$F, ">0") + COUNTIF(Baseline!$F:$F, "<0") + COUNTIF(Baseline!$F:$F, "=0")-D4-E4 -> 64 | D4: =COUNTIF(Baseline!$F:$F, ">0.05") + COUNTIF(Baseline!$F:$F, "<-0.05") - E4 -> 43 | E4: =COUNTIF(Baseline!$F:$F, ">0.10") + COUNTIF(Baseline!$F:$F, "<-0.10") -> 111 | F4: =SUM(C4:E4) -> 218 | I4: Baseline | J4: =(COUNTIF('1st Calibration Comparisons'!$C:$C, "none"))-K4-L4 -> 9 | K4: =COUNTIFS('1st Calibration Comparisons'!$C:$C, "none", '1st Calibration Comparisons'!$F:$F, ">0.05") + COUNTIFS('1st Calibration Comparisons'!$C:$C, "none", '1st Calibration Comparisons'!$F:$F, "<-0.05") -L4 -> 2 | L4: =COUNTIFS('1st Calibration Comparisons'!$C:$C, "none", '1st Calibration Comparisons'!$F:$F, ">0.10") + COUNTIFS('1st Calibration Comparisons'!$C:$C, "none", '1st Calibration Comparisons'!$F:$F, "<-0.10") -> 15 | M4: =SUM(J4:L4) -> 26
B5: 1st Calibration | C5: =(COUNTIF('1st Calibration'!$C:$C, "1st")) -D5-E5 -> 11 | D5: =COUNTIFS('1st Calibration'!$C:$C, "1st", '1st Calibration'!$F:$F, ">0.05") + COUNTIFS('1st Calibration'!$C:$C, "1st", '1st Calibration'!$F:$F, "<-0.05") -E5 -> 7 | E5: =COUNTIFS('1st Calibration'!$C:$C, "1st", '1st Calibration'!$F:$F, ">0.10") + COUNTIFS('1st Calibration'!$C:$C, "1st", '1st Calibration'!$F:$F, "<-0.10") -> 8 | F5: =SUM(C5:E5) -> 26 | I5: 1st Calibration | J5: =(COUNTIF('1st Calibration Comparisons'!$C:$C, "1st"))-K5-L5 -> 11 | K5: =COUNTIFS('1st Calibration Comparisons'!$C:$C, "1st", '1st Calibration Comparisons'!$F:$F, ">0.05") + COUNTIFS('1st Calibration Comparisons'!$C:$C, "1st", '1st Calibration Comparisons'!$F:$F, "<-0.05") -L5 -> 7 | L5: =COUNTIFS('1st Calibration Comparisons'!$C:$C, "1st", '1st Calibration Comparisons'!$F:$F, ">0.10") + COUNTIFS('1st Calibration Comparisons'!$C:$C, "1st", '1st Calibration Comparisons'!$F:$F, "<-0.10") -> 8 | M5: =SUM(J5:L5) -> 26
B6: % Improvement | C6: =(C5/$F$5)-(C4/$F$4) -> 0.12949894 | D6: =(D5/$F$5)-(D4/$F$4) -> 0.071983063 | E6: =(E5/$F$5)-(E4/$F$4) -> -0.201482 | I6: % Improvement | J6: =(J5/$M$5)-(J4/$M$4) -> 0.076923077 | K6: =(K5/$M$5)-(K4/$M$4) -> 0.19230769 | L6: =(L5/$M$5)-(L4/$M$4) -> -0.26923077
B7: 2nd Calibration | C7: =(COUNTIF('2nd Calibration'!$C:$C, "2nd")) -D7-E7 -> 2 | D7: =COUNTIFS('2nd Calibration'!$C:$C, "2nd", '2nd Calibration'!$F:$F, ">0.05") + COUNTIFS('2nd Calibration'!$C:$C, "2nd", '2nd Calibration'!$F:$F, "<-0.05") -E7 -> 1 | E7: =COUNTIFS('2nd Calibration'!$C:$C, "2nd", '2nd Calibration'!$F:$F, ">0.10") + COUNTIFS('2nd Calibration'!$C:$C, "2nd", '2nd Calibration'!$F:$F, "<-0.10") -> 1 | F7: =SUM(C7:E7) -> 4
B8: % Improvement | C8: =(C7/$F$7)-(C5/$F$5) -> 0.076923077 | D8: =(D7/$F$7)-(D5/$F$5) -> -0.019230769 | E8: =(E7/$F$7)-(E5/$F$5) -> -0.057692308
B10: Approach | I10: Approach
C11: Accurate 5% | D11: Acceptable (10%) | E11: Not-Acceptable (>10%) | F11: NA | G11: Total | J11: Accurate 5% | K11: Acceptable (10%) | L11: Not-Acceptable (>10%) | M11: NA
B12: Baseline | C12: =COUNTIF(Baseline!$G:$J, ">0") + COUNTIF(Baseline!$G:$J, "<0") + COUNTIF(Baseline!$G:$J, "=0")-D12-E12 -> 333 | D12: =COUNTIF(Baseline!$G:$J, ">0.05") + COUNTIF(Baseline!$G:$J, "<-0.05") -E12 -> 135 | E12: =COUNTIF(Baseline!$G:$J, ">0.10") + COUNTIF(Baseline!$G:$J, "<-0.10") -> 379 | F12: =COUNTIF(Baseline!$G:$J, "NA") -> 25 | G12: =SUM(C12:F12) -> 872 | I12: Baseline | J12: =(M4*4)-K12-L12-M12 -> 48 | K12: =COUNTIFS('1st Calibration Comparisons'!$C:$C,"none",'1st Calibration Comparisons'!$G:$G,">0.05")+COUNTIFS('1st Calibration Comparisons'!$C:$C,"none",'1st Calibration Comparisons'!$G:$G,"<-0.05")+COUNTIFS('1st Calibration Comparisons'!$C:$C,"none",'1st Calibration Comparisons'!$H:$H,">0.05")+COUNTIFS('1st Calibration Comparisons'!$C:$C,"none",'1st Calibration Comparisons'!$H:$H,"<-0.05")+COUNTIFS('1st Calibration Comparisons'!$C:$C,"none",'1st Calibration Comparisons'!$I:$I,">0.05")+COUNTIFS('1st Calibration Comparisons'!$C:$C,"none",'1st Calibration Comparisons'!$I:$I,"<-0.05") + COUNTIFS('1st Calibration Comparisons'!$C:$C, "none", '1st Calibration Comparisons'!$J:$J, ">0.05") + COUNTIFS('1st Calibration Comparisons'!$C:$C, "none", '1st Calibration Comparisons'!$J:$J, "<-0.05") -L12 -> 21 | L12: =COUNTIFS('1st Calibration Comparisons'!$C:$C,"none",'1st Calibration Comparisons'!$G:$G,"<-0.10") + COUNTIFS('1st Calibration Comparisons'!$C:$C,"none",'1st Calibration Comparisons'!$G:$G,">0.10") + COUNTIFS('1st Calibration Comparisons'!$C:$C,"none",'1st Calibration Comparisons'!$H:$H,"<-0.10") + COUNTIFS('1st Calibration Comparisons'!$C:$C,"none",'1st Calibration Comparisons'!$H:$H,">0.10") + COUNTIFS('1st Calibration Comparisons'!$C:$C,"none",'1st Calibration Comparisons'!$I:$I,"<-0.10") + COUNTIFS('1st Calibration Comparisons'!$C:$C,"none",'1st Calibration Comparisons'!$I:$I,">0.10") + COUNTIFS('1st Calibration Comparisons'!$C:$C,"none",'1st Calibration Comparisons'!$J:$J,"<-0.10") + COUNTIFS('1st Calibration Comparisons'!$C:$C,"none",'1st Calibration Comparisons'!$J:$J,">0.10") -> 33 | M12: =COUNTIFS('1st Calibration Comparisons'!$C:$C,"none",'1st Calibration Comparisons'!$G:$G,"NA") + COUNTIFS('1st Calibration Comparisons'!$C:$C,"none",'1st Calibration Comparisons'!$H:$H,"NA") + COUNTIFS('1st Calibration Comparisons'!$C:$C,"none",'1st Calibration Comparisons'!$I:$I,"NA") + COUNTIFS('1st Calibration Comparisons'!$C:$C,"none",'1st Calibration Comparisons'!$J:$J,"NA") -> 2 | N12: =SUM(J12:M12) -> 104
B13: 1st Calibration | C13: =(F5*4)-D13-E13-F13 -> 54 | D13: =COUNTIFS('1st Calibration'!$C:$C,"1st",'1st Calibration'!$G:$G,">0.05")+COUNTIFS('1st Calibration'!$C:$C,"1st",'1st Calibration'!$G:$G,"<-0.05")+COUNTIFS('1st Calibration'!$C:$C,"1st",'1st Calibration'!$H:$H,">0.05")+COUNTIFS('1st Calibration'!$C:$C,"1st",'1st Calibration'!$H:$H,"<-0.05")+COUNTIFS('1st Calibration'!$C:$C,"1st",'1st Calibration'!$I:$I,">0.05")+COUNTIFS('1st Calibration'!$C:$C,"1st",'1st Calibration'!$I:$I,"<-0.05") + COUNTIFS('1st Calibration'!$C:$C, "1st", '1st Calibration'!$J:$J, ">0.05") + COUNTIFS('1st Calibration'!$C:$C, "1st", '1st Calibration'!$J:$J, "<-0.05") -E13 -> 17 | E13: =COUNTIFS('1st Calibration'!$C:$C,"1st",'1st Calibration'!$G:$G,"<-0.10") + COUNTIFS('1st Calibration'!$C:$C,"1st",'1st Calibration'!$G:$G,">0.10") + COUNTIFS('1st Calibration'!$C:$C,"1st",'1st Calibration'!$H:$H,"<-0.10") + COUNTIFS('1st Calibration'!$C:$C,"1st",'1st Calibration'!$H:$H,">0.10") + COUNTIFS('1st Calibration'!$C:$C,"1st",'1st Calibration'!$I:$I,"<-0.10") + COUNTIFS('1st Calibration'!$C:$C,"1st",'1st Calibration'!$I:$I,">0.10") + COUNTIFS('1st Calibration'!$C:$C,"1st",'1st Calibration'!$J:$J,"<-0.10") + COUNTIFS('1st Calibration'!$C:$C,"1st",'1st Calibration'!$J:$J,">0.10") -> 30 | F13: =COUNTIFS('1st Calibration'!$C:$C,"1st",'1st Calibration'!$G:$G,"NA") + COUNTIFS('1st Calibration'!$C:$C,"1st",'1st Calibration'!$H:$H,"NA") + COUNTIFS('1st Calibration'!$C:$C,"1st",'1st Calibration'!$I:$I,"NA") + COUNTIFS('1st Calibration'!$C:$C,"1st",'1st Calibration'!$J:$J,"NA") -> 3 | G13: =SUM(C13:F13) -> 104 | I13: 1st Calibration | J13: =(M5*4)-K13-L13-M13 -> 54 | K13: =COUNTIFS('1st Calibration'!$C:$C,"1st",'1st Calibration'!$G:$G,">0.05")+COUNTIFS('1st Calibration'!$C:$C,"1st",'1st Calibration'!$G:$G,"<-0.05")+COUNTIFS('1st Calibration'!$C:$C,"1st",'1st Calibration'!$H:$H,">0.05")+COUNTIFS('1st Calibration'!$C:$C,"1st",'1st Calibration'!$H:$H,"<-0.05")+COUNTIFS('1st Calibration'!$C:$C,"1st",'1st Calibration'!$I:$I,">0.05")+COUNTIFS('1st Calibration'!$C:$C,"1st",'1st Calibration'!$I:$I,"<-0.05") + COUNTIFS('1st Calibration'!$C:$C, "1st", '1st Calibration'!$J:$J, ">0.05") + COUNTIFS('1st Calibration'!$C:$C, "1st", '1st Calibration'!$J:$J, "<-0.05") -L13 -> 17 | L13: =COUNTIFS('1st Calibration'!$C:$C,"1st",'1st Calibration'!$G:$G,"<-0.10") + COUNTIFS('1st Calibration'!$C:$C,"1st",'1st Calibration'!$G:$G,">0.10") + COUNTIFS('1st Calibration'!$C:$C,"1st",'1st Calibration'!$H:$H,"<-0.10") + COUNTIFS('1st Calibration'!$C:$C,"1st",'1st Calibration'!$H:$H,">0.10") + COUNTIFS('1st Calibration'!$C:$C,"1st",'1st Calibration'!$I:$I,"<-0.10") + COUNTIFS('1st Calibration'!$C:$C,"1st",'1st Calibration'!$I:$I,">0.10") + COUNTIFS('1st Calibration'!$C:$C,"1st",'1st Calibration'!$J:$J,"<-0.10") + COUNTIFS('1st Calibration'!$C:$C,"1st",'1st Calibration'!$J:$J,">0.10") -> 30 | M13: =COUNTIFS('1st Calibration'!$C:$C,"1st",'1st Calibration'!$G:$G,"NA") + COUNTIFS('1st Calibration'!$C:$C,"1st",'1st Calibration'!$H:$H,"NA") + COUNTIFS('1st Calibration'!$C:$C,"1st",'1st Calibration'!$I:$I,"NA") + COUNTIFS('1st Calibration'!$C:$C,"1st",'1st Calibration'!$J:$J,"NA") -> 3 | N13: =SUM(J13:M13) -> 104
B14: % Improvement | C14: =(C13/$G$13)-(C12/$G$12) -> 0.13735004 | D14: =(D13/$G$13)-(D12/$G$12) -> 0.0086450247 | E14: =(E13/$G$13)-(E12/$G$12) -> -0.14617149 | F14: =(F13/$G$13)-(F12/$G$12) -> 0.00017642908 | I14: % Improvement | J14: =(J13/$N$13)-(J12/$N$12) -> 0.057692308 | K14: =(K13/$N$13)-(K12/$N$12) -> -0.038461538 | L14: =(L13/$N$13)-(L12/$N$12) -> -0.028846154 | M14: =(M13/$N$13)-(M12/$N$12) -> 0.0096153846
B15: 2nd Calibration | C15: =(F7*4)-D15-E15-F15 -> 10 | D15: =COUNTIFS('2nd Calibration'!$C:$C,"2nd",'2nd Calibration'!$G:$G,">0.05")+COUNTIFS('2nd Calibration'!$C:$C,"2nd",'2nd Calibration'!$G:$G,"<-0.05")+COUNTIFS('2nd Calibration'!$C:$C,"2nd",'2nd Calibration'!$H:$H,">0.05")+COUNTIFS('2nd Calibration'!$C:$C,"2nd",'2nd Calibration'!$H:$H,"<-0.05")+COUNTIFS('2nd Calibration'!$C:$C,"2nd",'2nd Calibration'!$I:$I,">0.05")+COUNTIFS('2nd Calibration'!$C:$C,"2nd",'2nd Calibration'!$I:$I,"<-0.05") + COUNTIFS('2nd Calibration'!$C:$C, "2nd", '2nd Calibration'!$J:$J, ">0.05") + COUNTIFS('2nd Calibration'!$C:$C, "2nd", '2nd Calibration'!$J:$J, "<-0.05") -E15 -> 2 | E15: =COUNTIFS('2nd Calibration'!$C:$C,"2nd",'2nd Calibration'!$G:$G,"<-0.10") + COUNTIFS('2nd Calibration'!$C:$C,"2nd",'2nd Calibration'!$G:$G,">0.10") + COUNTIFS('2nd Calibration'!$C:$C,"2nd",'2nd Calibration'!$H:$H,"<-0.10") + COUNTIFS('2nd Calibration'!$C:$C,"2nd",'2nd Calibration'!$H:$H,">0.10") + COUNTIFS('2nd Calibration'!$C:$C,"2nd",'2nd Calibration'!$I:$I,"<-0.10") + COUNTIFS('2nd Calibration'!$C:$C,"2nd",'2nd Calibration'!$I:$I,">0.10") + COUNTIFS('2nd Calibration'!$C:$C,"2nd",'2nd Calibration'!$J:$J,"<-0.10") + COUNTIFS('2nd Calibration'!$C:$C,"2nd",'2nd Calibration'!$J:$J,">0.10") -> 3 | F15: =COUNTIFS('2nd Calibration'!$C:$C,"2nd",'2nd Calibration'!$G:$G,"NA") + COUNTIFS('2nd Calibration'!$C:$C,"2nd",'2nd Calibration'!$H:$H,"NA") + COUNTIFS('2nd Calibration'!$C:$C,"2nd",'2nd Calibration'!$I:$I,"NA") + COUNTIFS('2nd Calibration'!$C:$C,"2nd",'2nd Calibration'!$J:$J,"NA") -> 1 | G15: =SUM(C15:F15) -> 16
B16: % Improvement | C16: =(C15/$G$15)-(C13/$G$13) -> 0.10576923 | D16: =(D15/$G$15)-(D13/$G$13) -> -0.038461538 | E16: =(E15/$G$15)-(E13/$G$13) -> -0.10096154 | F16: =(F15/$G$15)-(F13/$G$13) -> 0.033653846
B18: Movement | I18: Approach
C19: Accurate 5% | D19: Acceptable (10%) | E19: Not-Acceptable (>10%) | F19: NA | G19: Total | J19: Accurate 5% | K19: Acceptable (10%) | L19: Not-Acceptable (>10%) | M19: NA
B20: Baseline | C20: =COUNTIF(Baseline!$K:$V, ">0") + COUNTIF(Baseline!$K:$V, "<0") + COUNTIF(Baseline!$K:$V, "=0")-D20-E20 -> 977 | D20: =COUNTIF(Baseline!$K:$V, ">0.05") + COUNTIF(Baseline!$K:$V, "<-0.05") -E20 -> 276 | E20: =COUNTIF(Baseline!$K:$V, ">0.10") + COUNTIF(Baseline!$K:$V, "<-0.10") -> 1240 | F20: =COUNTIF(Baseline!$K:$V, "NA") -> 121 | G20: =SUM(C20:F20) -> 2614 | I20: Baseline | J20: =(N12*3)-K20-L20-M20 -> 114 | K20: =COUNTIFS('1st Calibration Comparisons'!$C:$C,"none",'1st Calibration Comparisons'!$K:$K,"<-0.05") + COUNTIFS('1st Calibration Comparisons'!$C:$C,"none",'1st Calibration Comparisons'!$K:$K,">0.05") + COUNTIFS('1st Calibration Comparisons'!$C:$C,"none",'1st Calibration Comparisons'!$L:$L,"<-0.05") + COUNTIFS('1st Calibration Comparisons'!$C:$C,"none",'1st Calibration Comparisons'!$L:$L,">0.05") + COUNTIFS('1st Calibration Comparisons'!$C:$C,"none",'1st Calibration Comparisons'!$M:$M,"<-0.05") + COUNTIFS('1st Calibration Comparisons'!$C:$C,"none",'1st Calibration Comparisons'!$M:$M,">0.05") + COUNTIFS('1st Calibration Comparisons'!$C:$C,"none",'1st Calibration Comparisons'!$N:$N,"<-0.05") + COUNTIFS('1st Calibration Comparisons'!$C:$C,"none",'1st Calibration Comparisons'!$N:$N,">0.05") + COUNTIFS('1st Calibration Comparisons'!$C:$C,"none",'1st Calibration Comparisons'!$O:$O,"<-0.05") + COUNTIFS('1st Calibration Comparisons'!$C:$C,"none",'1st Calibration Comparisons'!$O:$O,">0.05") + COUNTIFS('1st Calibration Comparisons'!$C:$C,"none",'1st Calibration Comparisons'!$P:$P,"<-0.05") + COUNTIFS('1st Calibration Comparisons'!$C:$C,"none",'1st Calibration Comparisons'!$P:$P,">0.05") + COUNTIFS('1st Calibration Comparisons'!$C:$C,"none",'1st Calibration Comparisons'!$Q:$Q,"<-0.05") + COUNTIFS('1st Calibration Comparisons'!$C:$C,"none",'1st Calibration Comparisons'!$Q:$Q,">0.05") + COUNTIFS('1st Calibration Comparisons'!$C:$C,"none",'1st Calibration Comparisons'!$R:$R,"<-0.05") + COUNTIFS('1st Calibration Comparisons'!$C:$C,"none",'1st Calibration Comparisons'!$R:$R,">0.05") + COUNTIFS('1st Calibration Comparisons'!$C:$C,"none",'1st Calibration Comparisons'!$S:$S,"<-0.05") + COUNTIFS('1st Calibration Comparisons'!$C:$C,"none",'1st Calibration Comparisons'!$S:$S,">0.05") + COUNTIFS('1st Calibration Comparisons'!$C:$C,"none",'1st Calibration Comparisons'!$T:$T,"<-0.05") + COUNTIFS('1st Calibration Comparisons'!$C:$C,"none",'1st Calibration Comparisons'!$T:$T,">0.05") + COUNTIFS('1st Calibration Comparisons'!$C:$C,"none",'1st Calibration Comparisons'!$U:$U,"<-0.05") + COUNTIFS('1st Calibration Comparisons'!$C:$C,"none",'1st Calibration Comparisons'!$U:$U,">0.05") + COUNTIFS('1st Calibration Comparisons'!$C:$C,"none",'1st Calibration Comparisons'!$V:$V,"<-0.05") + COUNTIFS('1st Calibration Comparisons'!$C:$C,"none",'1st Calibration Comparisons'!$V:$V,">0.05") -L20 -> 44 | L20: =COUNTIFS('1st Calibration Comparisons'!$C:$C,"none",'1st Calibration Comparisons'!$K:$K,"<-0.10") + COUNTIFS('1st Calibration Comparisons'!$C:$C,"none",'1st Calibration Comparisons'!$K:$K,">0.10") + COUNTIFS('1st Calibration Comparisons'!$C:$C,"none",'1st Calibration Comparisons'!$L:$L,"<-0.10") + COUNTIFS('1st Calibration Comparisons'!$C:$C,"none",'1st Calibration Comparisons'!$L:$L,">0.10") + COUNTIFS('1st Calibration Comparisons'!$C:$C,"none",'1st Calibration Comparisons'!$M:$M,"<-0.10") + COUNTIFS('1st Calibration Comparisons'!$C:$C,"none",'1st Calibration Comparisons'!$M:$M,">0.10") + COUNTIFS('1st Calibration Comparisons'!$C:$C,"none",'1st Calibration Comparisons'!$N:$N,"<-0.10") + COUNTIFS('1st Calibration Comparisons'!$C:$C,"none",'1st Calibration Comparisons'!$N:$N,">0.10") + COUNTIFS('1st Calibration Comparisons'!$C:$C,"none",'1st Calibration Comparisons'!$O:$O,"<-0.10") + COUNTIFS('1st Calibration Comparisons'!$C:$C,"none",'1st Calibration Comparisons'!$O:$O,">0.10") + COUNTIFS('1st Calibration Comparisons'!$C:$C,"none",'1st Calibration Comparisons'!$P:$P,"<-0.10") + COUNTIFS('1st Calibration Comparisons'!$C:$C,"none",'1st Calibration Comparisons'!$P:$P,">0.10") + COUNTIFS('1st Calibration Comparisons'!$C:$C,"none",'1st Calibration Comparisons'!$Q:$Q,"<-0.10") + COUNTIFS('1st Calibration Comparisons'!$C:$C,"none",'1st Calibration Comparisons'!$Q:$Q,">0.10") + COUNTIFS('1st Calibration Comparisons'!$C:$C,"none",'1st Calibration Comparisons'!$R:$R,"<-0.10") + COUNTIFS('1st Calibration Comparisons'!$C:$C,"none",'1st Calibration Comparisons'!$R:$R,">0.10") + COUNTIFS('1st Calibration Comparisons'!$C:$C,"none",'1st Calibration Comparisons'!$S:$S,"<-0.10") + COUNTIFS('1st Calibration Comparisons'!$C:$C,"none",'1st Calibration Comparisons'!$S:$S,">0.10") + COUNTIFS('1st Calibration Comparisons'!$C:$C,"none",'1st Calibration Comparisons'!$T:$T,"<-0.10") + COUNTIFS('1st Calibration Comparisons'!$C:$C,"none",'1st Calibration Comparisons'!$T:$T,">0.10") + COUNTIFS('1st Calibration Comparisons'!$C:$C,"none",'1st Calibration Comparisons'!$U:$U,"<-0.10") + COUNTIFS('1st Calibration Comparisons'!$C:$C,"none",'1st Calibration Comparisons'!$U:$U,">0.10") + COUNTIFS('1st Calibration Comparisons'!$C:$C,"none",'1st Calibration Comparisons'!$V:$V,"<-0.10") + COUNTIFS('1st Calibration Comparisons'!$C:$C,"none",'1st Calibration Comparisons'!$V:$V,">0.10") -> 145 | M20: =COUNTIFS('1st Calibration Comparisons'!$C:$C,"none",'1st Calibration Comparisons'!$K:$K,"NA")+COUNTIFS('1st Calibration Comparisons'!$C:$C,"none",'1st Calibration Comparisons'!$L:$L,"NA")+COUNTIFS('1st Calibration Comparisons'!$C:$C,"none",'1st Calibration Comparisons'!$M:$M,"NA")+COUNTIFS('1st Calibration Comparisons'!$C:$C,"none",'1st Calibration Comparisons'!$N:$N,"NA")+COUNTIFS('1st Calibration Comparisons'!$C:$C,"none",'1st Calibration Comparisons'!$O:$O,"NA")+COUNTIFS('1st Calibration Comparisons'!$C:$C,"none",'1st Calibration Comparisons'!$P:$P,"NA")+COUNTIFS('1st Calibration Comparisons'!$C:$C,"none",'1st Calibration Comparisons'!$Q:$Q,"NA")+COUNTIFS('1st Calibration Comparisons'!$C:$C,"none",'1st Calibration Comparisons'!$R:$R,"NA")+COUNTIFS('1st Calibration Comparisons'!$C:$C,"none",'1st Calibration Comparisons'!$S:$S,"NA")+COUNTIFS('1st Calibration Comparisons'!$C:$C,"none",'1st Calibration Comparisons'!$T:$T,"NA")+COUNTIFS('1st Calibration Comparisons'!$C:$C,"none",'1st Calibration Comparisons'!$U:$U,"NA")++COUNTIFS('1st Calibration Comparisons'!$C:$C,"none",'1st Calibration Comparisons'!$V:$V,"NA") -> 9 | N20: =SUM(J20:M20) -> 312
B21: 1st Calibration | C21: =(F5*12)-D21-E21-F21 -> 121 | D21: =COUNTIFS('1st Calibration'!$C:$C,"1st",'1st Calibration'!$K:$K,"<-0.05") + COUNTIFS('1st Calibration'!$C:$C,"1st",'1st Calibration'!$K:$K,">0.05") + COUNTIFS('1st Calibration'!$C:$C,"1st",'1st Calibration'!$L:$L,"<-0.05") + COUNTIFS('1st Calibration'!$C:$C,"1st",'1st Calibration'!$L:$L,">0.05") + COUNTIFS('1st Calibration'!$C:$C,"1st",'1st Calibration'!$M:$M,"<-0.05") + COUNTIFS('1st Calibration'!$C:$C,"1st",'1st Calibration'!$M:$M,">0.05") + COUNTIFS('1st Calibration'!$C:$C,"1st",'1st Calibration'!$N:$N,"<-0.05") + COUNTIFS('1st Calibration'!$C:$C,"1st",'1st Calibration'!$N:$N,">0.05") + COUNTIFS('1st Calibration'!$C:$C,"1st",'1st Calibration'!$O:$O,"<-0.05") + COUNTIFS('1st Calibration'!$C:$C,"1st",'1st Calibration'!$O:$O,">0.05") + COUNTIFS('1st Calibration'!$C:$C,"1st",'1st Calibration'!$P:$P,"<-0.05") + COUNTIFS('1st Calibration'!$C:$C,"1st",'1st Calibration'!$P:$P,">0.05") + COUNTIFS('1st Calibration'!$C:$C,"1st",'1st Calibration'!$Q:$Q,"<-0.05") + COUNTIFS('1st Calibration'!$C:$C,"1st",'1st Calibration'!$Q:$Q,">0.05") + COUNTIFS('1st Calibration'!$C:$C,"1st",'1st Calibration'!$R:$R,"<-0.05") + COUNTIFS('1st Calibration'!$C:$C,"1st",'1st Calibration'!$R:$R,">0.05") + COUNTIFS('1st Calibration'!$C:$C,"1st",'1st Calibration'!$S:$S,"<-0.05") + COUNTIFS('1st Calibration'!$C:$C,"1st",'1st Calibration'!$S:$S,">0.05") + COUNTIFS('1st Calibration'!$C:$C,"1st",'1st Calibration'!$T:$T,"<-0.05") + COUNTIFS('1st Calibration'!$C:$C,"1st",'1st Calibration'!$T:$T,">0.05") + COUNTIFS('1st Calibration'!$C:$C,"1st",'1st Calibration'!$U:$U,"<-0.05") + COUNTIFS('1st Calibration'!$C:$C,"1st",'1st Calibration'!$U:$U,">0.05") + COUNTIFS('1st Calibration'!$C:$C,"1st",'1st Calibration'!$V:$V,"<-0.05") + COUNTIFS('1st Calibration'!$C:$C,"1st",'1st Calibration'!$V:$V,">0.05") -E21 -> 48 | E21: =COUNTIFS('1st Calibration'!$C:$C,"1st",'1st Calibration'!$K:$K,"<-0.10") + COUNTIFS('1st Calibration'!$C:$C,"1st",'1st Calibration'!$K:$K,">0.10") + COUNTIFS('1st Calibration'!$C:$C,"1st",'1st Calibration'!$L:$L,"<-0.10") + COUNTIFS('1st Calibration'!$C:$C,"1st",'1st Calibration'!$L:$L,">0.10") + COUNTIFS('1st Calibration'!$C:$C,"1st",'1st Calibration'!$M:$M,"<-0.10") + COUNTIFS('1st Calibration'!$C:$C,"1st",'1st Calibration'!$M:$M,">0.10") + COUNTIFS('1st Calibration'!$C:$C,"1st",'1st Calibration'!$N:$N,"<-0.10") + COUNTIFS('1st Calibration'!$C:$C,"1st",'1st Calibration'!$N:$N,">0.10") + COUNTIFS('1st Calibration'!$C:$C,"1st",'1st Calibration'!$O:$O,"<-0.10") + COUNTIFS('1st Calibration'!$C:$C,"1st",'1st Calibration'!$O:$O,">0.10") + COUNTIFS('1st Calibration'!$C:$C,"1st",'1st Calibration'!$P:$P,"<-0.10") + COUNTIFS('1st Calibration'!$C:$C,"1st",'1st Calibration'!$P:$P,">0.10") + COUNTIFS('1st Calibration'!$C:$C,"1st",'1st Calibration'!$Q:$Q,"<-0.10") + COUNTIFS('1st Calibration'!$C:$C,"1st",'1st Calibration'!$Q:$Q,">0.10") + COUNTIFS('1st Calibration'!$C:$C,"1st",'1st Calibration'!$R:$R,"<-0.10") + COUNTIFS('1st Calibration'!$C:$C,"1st",'1st Calibration'!$R:$R,">0.10") + COUNTIFS('1st Calibration'!$C:$C,"1st",'1st Calibration'!$S:$S,"<-0.10") + COUNTIFS('1st Calibration'!$C:$C,"1st",'1st Calibration'!$S:$S,">0.10") + COUNTIFS('1st Calibration'!$C:$C,"1st",'1st Calibration'!$T:$T,"<-0.10") + COUNTIFS('1st Calibration'!$C:$C,"1st",'1st Calibration'!$T:$T,">0.10") + COUNTIFS('1st Calibration'!$C:$C,"1st",'1st Calibration'!$U:$U,"<-0.10") + COUNTIFS('1st Calibration'!$C:$C,"1st",'1st Calibration'!$U:$U,">0.10") + COUNTIFS('1st Calibration'!$C:$C,"1st",'1st Calibration'!$V:$V,"<-0.10") + COUNTIFS('1st Calibration'!$C:$C,"1st",'1st Calibration'!$V:$V,">0.10") -> 127 | F21: =COUNTIFS('1st Calibration'!$C:$C,"1st",'1st Calibration'!$K:$K,"NA")+COUNTIFS('1st Calibration'!$C:$C,"1st",'1st Calibration'!$L:$L,"NA")+COUNTIFS('1st Calibration'!$C:$C,"1st",'1st Calibration'!$M:$M,"NA")+COUNTIFS('1st Calibration'!$C:$C,"1st",'1st Calibration'!$N:$N,"NA")+COUNTIFS('1st Calibration'!$C:$C,"1st",'1st Calibration'!$O:$O,"NA")+COUNTIFS('1st Calibration'!$C:$C,"1st",'1st Calibration'!$P:$P,"NA")+COUNTIFS('1st Calibration'!$C:$C,"1st",'1st Calibration'!$Q:$Q,"NA")+COUNTIFS('1st Calibration'!$C:$C,"1st",'1st Calibration'!$R:$R,"NA")+COUNTIFS('1st Calibration'!$C:$C,"1st",'1st Calibration'!$S:$S,"NA")+COUNTIFS('1st Calibration'!$C:$C,"1st",'1st Calibration'!$T:$T,"NA")+COUNTIFS('1st Calibration'!$C:$C,"1st",'1st Calibration'!$U:$U,"NA")++COUNTIFS('1st Calibration'!$C:$C,"1st",'1st Calibration'!$V:$V,"NA") -> 16 | G21: =SUM(C21:F21) -> 312 | I21: 1st Calibration | J21: =(M5*12)-K21-L21-M21 -> 121 | K21: =COUNTIFS('1st Calibration'!$C:$C,"1st",'1st Calibration'!$K:$K,"<-0.05") + COUNTIFS('1st Calibration'!$C:$C,"1st",'1st Calibration'!$K:$K,">0.05") + COUNTIFS('1st Calibration'!$C:$C,"1st",'1st Calibration'!$L:$L,"<-0.05") + COUNTIFS('1st Calibration'!$C:$C,"1st",'1st Calibration'!$L:$L,">0.05") + COUNTIFS('1st Calibration'!$C:$C,"1st",'1st Calibration'!$M:$M,"<-0.05") + COUNTIFS('1st Calibration'!$C:$C,"1st",'1st Calibration'!$M:$M,">0.05") + COUNTIFS('1st Calibration'!$C:$C,"1st",'1st Calibration'!$N:$N,"<-0.05") + COUNTIFS('1st Calibration'!$C:$C,"1st",'1st Calibration'!$N:$N,">0.05") + COUNTIFS('1st Calibration'!$C:$C,"1st",'1st Calibration'!$O:$O,"<-0.05") + COUNTIFS('1st Calibration'!$C:$C,"1st",'1st Calibration'!$O:$O,">0.05") + COUNTIFS('1st Calibration'!$C:$C,"1st",'1st Calibration'!$P:$P,"<-0.05") + COUNTIFS('1st Calibration'!$C:$C,"1st",'1st Calibration'!$P:$P,">0.05") + COUNTIFS('1st Calibration'!$C:$C,"1st",'1st Calibration'!$Q:$Q,"<-0.05") + COUNTIFS('1st Calibration'!$C:$C,"1st",'1st Calibration'!$Q:$Q,">0.05") + COUNTIFS('1st Calibration'!$C:$C,"1st",'1st Calibration'!$R:$R,"<-0.05") + COUNTIFS('1st Calibration'!$C:$C,"1st",'1st Calibration'!$R:$R,">0.05") + COUNTIFS('1st Calibration'!$C:$C,"1st",'1st Calibration'!$S:$S,"<-0.05") + COUNTIFS('1st Calibration'!$C:$C,"1st",'1st Calibration'!$S:$S,">0.05") + COUNTIFS('1st Calibration'!$C:$C,"1st",'1st Calibration'!$T:$T,"<-0.05") + COUNTIFS('1st Calibration'!$C:$C,"1st",'1st Calibration'!$T:$T,">0.05") + COUNTIFS('1st Calibration'!$C:$C,"1st",'1st Calibration'!$U:$U,"<-0.05") + COUNTIFS('1st Calibration'!$C:$C,"1st",'1st Calibration'!$U:$U,">0.05") + COUNTIFS('1st Calibration'!$C:$C,"1st",'1st Calibration'!$V:$V,"<-0.05") + COUNTIFS('1st Calibration'!$C:$C,"1st",'1st Calibration'!$V:$V,">0.05") -L21 -> 48 | L21: =COUNTIFS('1st Calibration'!$C:$C,"1st",'1st Calibration'!$K:$K,"<-0.10") + COUNTIFS('1st Calibration'!$C:$C,"1st",'1st Calibration'!$K:$K,">0.10") + COUNTIFS('1st Calibration'!$C:$C,"1st",'1st Calibration'!$L:$L,"<-0.10") + COUNTIFS('1st Calibration'!$C:$C,"1st",'1st Calibration'!$L:$L,">0.10") + COUNTIFS('1st Calibration'!$C:$C,"1st",'1st Calibration'!$M:$M,"<-0.10") + COUNTIFS('1st Calibration'!$C:$C,"1st",'1st Calibration'!$M:$M,">0.10") + COUNTIFS('1st Calibration'!$C:$C,"1st",'1st Calibration'!$N:$N,"<-0.10") + COUNTIFS('1st Calibration'!$C:$C,"1st",'1st Calibration'!$N:$N,">0.10") + COUNTIFS('1st Calibration'!$C:$C,"1st",'1st Calibration'!$O:$O,"<-0.10") + COUNTIFS('1st Calibration'!$C:$C,"1st",'1st Calibration'!$O:$O,">0.10") + COUNTIFS('1st Calibration'!$C:$C,"1st",'1st Calibration'!$P:$P,"<-0.10") + COUNTIFS('1st Calibration'!$C:$C,"1st",'1st Calibration'!$P:$P,">0.10") + COUNTIFS('1st Calibration'!$C:$C,"1st",'1st Calibration'!$Q:$Q,"<-0.10") + COUNTIFS('1st Calibration'!$C:$C,"1st",'1st Calibration'!$Q:$Q,">0.10") + COUNTIFS('1st Calibration'!$C:$C,"1st",'1st Calibration'!$R:$R,"<-0.10") + COUNTIFS('1st Calibration'!$C:$C,"1st",'1st Calibration'!$R:$R,">0.10") + COUNTIFS('1st Calibration'!$C:$C,"1st",'1st Calibration'!$S:$S,"<-0.10") + COUNTIFS('1st Calibration'!$C:$C,"1st",'1st Calibration'!$S:$S,">0.10") + COUNTIFS('1st Calibration'!$C:$C,"1st",'1st Calibration'!$T:$T,"<-0.10") + COUNTIFS('1st Calibration'!$C:$C,"1st",'1st Calibration'!$T:$T,">0.10") + COUNTIFS('1st Calibration'!$C:$C,"1st",'1st Calibration'!$U:$U,"<-0.10") + COUNTIFS('1st Calibration'!$C:$C,"1st",'1st Calibration'!$U:$U,">0.10") + COUNTIFS('1st Calibration'!$C:$C,"1st",'1st Calibration'!$V:$V,"<-0.10") + COUNTIFS('1st Calibration'!$C:$C,"1st",'1st Calibration'!$V:$V,">0.10") -> 127 | M21: =COUNTIFS('1st Calibration'!$C:$C,"1st",'1st Calibration'!$K:$K,"NA")+COUNTIFS('1st Calibration'!$C:$C,"1st",'1st Calibration'!$L:$L,"NA")+COUNTIFS('1st Calibration'!$C:$C,"1st",'1st Calibration'!$M:$M,"NA")+COUNTIFS('1st Calibration'!$C:$C,"1st",'1st Calibration'!$N:$N,"NA")+COUNTIFS('1st Calibration'!$C:$C,"1st",'1st Calibration'!$O:$O,"NA")+COUNTIFS('1st Calibration'!$C:$C,"1st",'1st Calibration'!$P:$P,"NA")+COUNTIFS('1st Calibration'!$C:$C,"1st",'1st Calibration'!$Q:$Q,"NA")+COUNTIFS('1st Calibration'!$C:$C,"1st",'1st Calibration'!$R:$R,"NA")+COUNTIFS('1st Calibration'!$C:$C,"1st",'1st Calibration'!$S:$S,"NA")+COUNTIFS('1st Calibration'!$C:$C,"1st",'1st Calibration'!$T:$T,"NA")+COUNTIFS('1st Calibration'!$C:$C,"1st",'1st Calibration'!$U:$U,"NA")++COUNTIFS('1st Calibration'!$C:$C,"1st",'1st Calibration'!$V:$V,"NA") -> 16 | N21: =SUM(J21:M21) -> 312
B22: % Improvement | C22: =(C21/$G$21)-(C20/$G$20) -> 0.014063818 | D22: =(D21/$G$21)-(D20/$G$20) -> 0.048260844 | E22: =(E21/$G$21)-(E20/$G$20) -> -0.067317501 | F22: =(F21/$G$21)-(F20/$G$20) -> 0.0049928393 | I22: % Improvement | J22: =(J21/$N$21)-(J20/$N$20) -> 0.022435897 | K22: =(K21/$N$21)-(K20/$N$20) -> 0.012820513 | L22: =(L21/$N$21)-(L20/$N$20) -> -0.057692308 | M22: =(M21/$N$21)-(M20/$N$20) -> 0.022435897
B23: 2nd Calibration | C23: =(F7*12)-D23-E23-F23 -> 28 | D23: =COUNTIFS('2nd Calibration'!$C:$C,"2nd",'2nd Calibration'!$K:$K,"<-0.05") + COUNTIFS('2nd Calibration'!$C:$C,"2nd",'2nd Calibration'!$K:$K,">0.05") + COUNTIFS('2nd Calibration'!$C:$C,"2nd",'2nd Calibration'!$L:$L,"<-0.05") + COUNTIFS('2nd Calibration'!$C:$C,"2nd",'2nd Calibration'!$L:$L,">0.05") + COUNTIFS('2nd Calibration'!$C:$C,"2nd",'2nd Calibration'!$M:$M,"<-0.05") + COUNTIFS('2nd Calibration'!$C:$C,"2nd",'2nd Calibration'!$M:$M,">0.05") + COUNTIFS('2nd Calibration'!$C:$C,"2nd",'2nd Calibration'!$N:$N,"<-0.05") + COUNTIFS('2nd Calibration'!$C:$C,"2nd",'2nd Calibration'!$N:$N,">0.05") + COUNTIFS('2nd Calibration'!$C:$C,"2nd",'2nd Calibration'!$O:$O,"<-0.05") + COUNTIFS('2nd Calibration'!$C:$C,"2nd",'2nd Calibration'!$O:$O,">0.05") + COUNTIFS('2nd Calibration'!$C:$C,"2nd",'2nd Calibration'!$P:$P,"<-0.05") + COUNTIFS('2nd Calibration'!$C:$C,"2nd",'2nd Calibration'!$P:$P,">0.05") + COUNTIFS('2nd Calibration'!$C:$C,"2nd",'2nd Calibration'!$Q:$Q,"<-0.05") + COUNTIFS('2nd Calibration'!$C:$C,"2nd",'2nd Calibration'!$Q:$Q,">0.05") + COUNTIFS('2nd Calibration'!$C:$C,"2nd",'2nd Calibration'!$R:$R,"<-0.05") + COUNTIFS('2nd Calibration'!$C:$C,"2nd",'2nd Calibration'!$R:$R,">0.05") + COUNTIFS('2nd Calibration'!$C:$C,"2nd",'2nd Calibration'!$S:$S,"<-0.05") + COUNTIFS('2nd Calibration'!$C:$C,"2nd",'2nd Calibration'!$S:$S,">0.05") + COUNTIFS('2nd Calibration'!$C:$C,"2nd",'2nd Calibration'!$T:$T,"<-0.05") + COUNTIFS('2nd Calibration'!$C:$C,"2nd",'2nd Calibration'!$T:$T,">0.05") + COUNTIFS('2nd Calibration'!$C:$C,"2nd",'2nd Calibration'!$U:$U,"<-0.05") + COUNTIFS('2nd Calibration'!$C:$C,"2nd",'2nd Calibration'!$U:$U,">0.05") + COUNTIFS('2nd Calibration'!$C:$C,"2nd",'2nd Calibration'!$V:$V,"<-0.05") + COUNTIFS('2nd Calibration'!$C:$C,"2nd",'2nd Calibration'!$V:$V,">0.05") -E23 -> 4 | E23: =COUNTIFS('2nd Calibration'!$C:$C,"2nd",'2nd Calibration'!$K:$K,"<-0.10") + COUNTIFS('2nd Calibration'!$C:$C,"2nd",'2nd Calibration'!$K:$K,">0.10") + COUNTIFS('2nd Calibration'!$C:$C,"2nd",'2nd Calibration'!$L:$L,"<-0.10") + COUNTIFS('2nd Calibration'!$C:$C,"2nd",'2nd Calibration'!$L:$L,">0.10") + COUNTIFS('2nd Calibration'!$C:$C,"2nd",'2nd Calibration'!$M:$M,"<-0.10") + COUNTIFS('2nd Calibration'!$C:$C,"2nd",'2nd Calibration'!$M:$M,">0.10") + COUNTIFS('2nd Calibration'!$C:$C,"2nd",'2nd Calibration'!$N:$N,"<-0.10") + COUNTIFS('2nd Calibration'!$C:$C,"2nd",'2nd Calibration'!$N:$N,">0.10") + COUNTIFS('2nd Calibration'!$C:$C,"2nd",'2nd Calibration'!$O:$O,"<-0.10") + COUNTIFS('2nd Calibration'!$C:$C,"2nd",'2nd Calibration'!$O:$O,">0.10") + COUNTIFS('2nd Calibration'!$C:$C,"2nd",'2nd Calibration'!$P:$P,"<-0.10") + COUNTIFS('2nd Calibration'!$C:$C,"2nd",'2nd Calibration'!$P:$P,">0.10") + COUNTIFS('2nd Calibration'!$C:$C,"2nd",'2nd Calibration'!$Q:$Q,"<-0.10") + COUNTIFS('2nd Calibration'!$C:$C,"2nd",'2nd Calibration'!$Q:$Q,">0.10") + COUNTIFS('2nd Calibration'!$C:$C,"2nd",'2nd Calibration'!$R:$R,"<-0.10") + COUNTIFS('2nd Calibration'!$C:$C,"2nd",'2nd Calibration'!$R:$R,">0.10") + COUNTIFS('2nd Calibration'!$C:$C,"2nd",'2nd Calibration'!$S:$S,"<-0.10") + COUNTIFS('2nd Calibration'!$C:$C,"2nd",'2nd Calibration'!$S:$S,">0.10") + COUNTIFS('2nd Calibration'!$C:$C,"2nd",'2nd Calibration'!$T:$T,"<-0.10") + COUNTIFS('2nd Calibration'!$C:$C,"2nd",'2nd Calibration'!$T:$T,">0.10") + COUNTIFS('2nd Calibration'!$C:$C,"2nd",'2nd Calibration'!$U:$U,"<-0.10") + COUNTIFS('2nd Calibration'!$C:$C,"2nd",'2nd Calibration'!$U:$U,">0.10") + COUNTIFS('2nd Calibration'!$C:$C,"2nd",'2nd Calibration'!$V:$V,"<-0.10") + COUNTIFS('2nd Calibration'!$C:$C,"2nd",'2nd Calibration'!$V:$V,">0.10") -> 11 | F23: =COUNTIFS('2nd Calibration'!$C:$C,"2nd",'2nd Calibration'!$K:$K,"NA")+COUNTIFS('2nd Calibration'!$C:$C,"2nd",'2nd Calibration'!$L:$L,"NA")+COUNTIFS('2nd Calibration'!$C:$C,"2nd",'2nd Calibration'!$M:$M,"NA")+COUNTIFS('2nd Calibration'!$C:$C,"2nd",'2nd Calibration'!$N:$N,"NA")+COUNTIFS('2nd Calibration'!$C:$C,"2nd",'2nd Calibration'!$O:$O,"NA")+COUNTIFS('2nd Calibration'!$C:$C,"2nd",'2nd Calibration'!$P:$P,"NA")+COUNTIFS('2nd Calibration'!$C:$C,"2nd",'2nd Calibration'!$Q:$Q,"NA")+COUNTIFS('2nd Calibration'!$C:$C,"2nd",'2nd Calibration'!$R:$R,"NA")+COUNTIFS('2nd Calibration'!$C:$C,"2nd",'2nd Calibration'!$S:$S,"NA")+COUNTIFS('2nd Calibration'!$C:$C,"2nd",'2nd Calibration'!$T:$T,"NA")+COUNTIFS('2nd Calibration'!$C:$C,"2nd",'2nd Calibration'!$U:$U,"NA")++COUNTIFS('2nd Calibration'!$C:$C,"2nd",'2nd Calibration'!$V:$V,"NA") -> 5 | G23: =SUM(C23:F23) -> 48
B24: % Improvement | C24: =(C23/$G$23)-(C21/$G$21) -> 0.19551282 | D24: =(D23/$G$23)-(D21/$G$21) -> -0.070512821 | E24: =(E23/$G$23)-(E21/$G$21) -> -0.17788462 | F24: =(F23/$G$23)-(F21/$G$21) -> 0.052884615

Sheet 1st Calibration
A1: ID | B1: Intersection | C1: Calibration # | D1: Date | E1: Time of Day | F1: Total | G1: EB Total | H1: WB Total | I1: NB Total | J1: SB Total | K1: EBL | L1: EBT | M1: EBR | N1: WBL | O1: WBT | P1: WBR | Q1: NBL | R1: NBT | S1: NBR | T1: SBL | U1: SBT | V1: SBR
A2: 8059100 | B2: CR 101 (Brockton Ln) at Dayton Parkway | C2: NA | D2: NA | E2: NA
A3: 8008400 | B3: CSAH 1 (Old Shakopee Rd) at CSAH 17 (France Ave) | C3: 1st Calibration | D3: 45841 | E3: 0.53125 | F3: 0.0578 | G3: 0.0386 | H3: 0.1326 | I3: 0.0227 | J3: -0.0107 | K3: 0.0267 | L3: -0.0161 | M3: 0.4 | N3: 0 | O3: 0.1075 | P3: 0.32 | Q3: 0 | R3: 0 | S3: 0.1 | T3: -0.0282 | U3: -0.0465 | V3: 0.0274 | Y3: Collected By: | AA3: Sauharda Shrestha
A4: 8018400 | B4: CSAH 1 (Old Shakopee Rd) at CSAH 34 (Normandale Blvd) | C4: 1st Calibration | D4: 45841 | E4: 0.53125 | F4: -0.1641 | G4: -0.0615 | H4: -0.0269 | I4: -0.5263 | J4: -0.5108 | K4: -0.0645 | L4: 0.0317 | M4: -2 | N4: 0.0714 | O4: -0.0588 | P4: 0.08 | Q4: 0 | R4: 0 | S4: -2 | T4: 0.0889 | U4: 0.1081 | V4: -2 | Y4: Collected By: | AA4: Sauharda Shrestha
A5: 8044600 | B5: CSAH 1 (Old Shakopee Rd) at Nesbitt Ave | C5: 1st Calibration | D5: 45845 | E5: 0.53125 | F5: -0.0107 | G5: 0.0119 | H5: -0.0371 | I5: 0.1053 | J5: -0.1111 | K5: 0 | L5: -0.0044 | M5: 0.3636 | N5: 0 | O5: -0.0423 | P5: 0 | Q5: 0.1176 | R5: 0 | S5: 0 | T5: 0 | U5: 0 | V5: -0.25 | Y5: Collected By: | AA5: Sauharda Shrestha
A6: 8022400 | B6: CSAH 1 (Old Shakopee Rd) at Xerxes Ave S | C6: 1st Calibration | D6: 45845 | E6: 0.625 | F6: -0.2714 | G6: -0.0112 | H6: -0.3077 | I6: -1.5556 | J6: 0.0952 | K6: 0 | L6: -0.0116 | M6: 0 | N6: -0.8 | O6: -0.2769 | P6: -2 | Q6: -1.9259 | R6: -0.6667 | S6: -1.3333 | T6: 0.1333 | U6: 0.1053 | V6: 0 | Y6: Collected By: | AA6: Sauharda Shrestha
A7: 8052100 | B7: CSAH 1 (Pioneer Trail) at Bennett Place | C7: 1st Calibration | D7: 45839 | E7: 0.625 | F7: -0.1247 | G7: -0.186 | H7: -0.05 | I7: 0 | J7: -0.08 | K7: 0 | L7: -0.1345 | M7: -1 | N7: -0.2222 | O7: -0.0845 | P7: 0.6667 | Q7: 0 | R7: 0 | S7: 0 | T7: -0.1176 | U7: 2 | V7: -0.2857 | Y7: collected by | AA7: Sauharda Shrestha
A8: 8037200 | B8: CSAH 1 (Pioneer Trail) at CSAH 4 (Eden Prairie Rd) | C8: 1st Calibration | D8: 46015 | E8: 0.3125 | F8: -0.1023 | G8: 0.0588 | H8: 0.0465 | I8: -0.1091 | J8: -0.449 | K8: 0.24 | L8: -0.0513 | M8: 0 | N8: 0 | O8: 0.2857 | P8: -0.1818 | Q8: -0.4 | R8: 0.0444 | S8: -1.2 | T8: -0.3704 | U8: -0.6667 | V8: 0 | Y8: Collected by | AA8: Sauharda Shrestha
A9: 8057300 | B9: CSAH 1 (Pioneer Trail) at CSAH 61 (Flying Cloud Dr) | C9: 1st Calibration | D9: 46015 | E9: 0.33333333 | F9: 0.304 | G9: 0.5778 | H9: 0.3759 | I9: 0.0615 | J9: 0.2727 | K9: -0.08 | L9: 0.717 | M9: 1.3333 | N9: 0.1333 | O9: 0.6341 | P9: -0.1111 | Q9: 0 | R9: 0.0784 | S9: 0 | T9: -0.087 | U9: 0.4727 | V9: 0 | Y9: Collected by | AA9: Sauharda Shrestha
A10: 8051400 | B10: CSAH 1 (Pioneer Trail) at Dell Rd | C10: 1st Calibration | D10: 46020 | E10: 0.34375 | F10: 0.0995 | G10: 0.1474 | H10: 0.1379 | I10: 0 | J10: 0 | K10: 0.2105 | L10: 0.1224 | M10: 0 | N10: -2 | O10: 0.1538 | P10: 0.1935 | Q10: 0 | R10: 0 | S10: 0 | T10: -0.25 | U10: 0.2222 | V10: 0.2857 | Y10: Collected By | AA10: Sauharda Shrestha
A11: 8037400 | B11: CSAH 1 (Pioneer Trail) at Franlo Rd | C11: 1st Calibration | D11: 45814 | E11: 0.32291667 | F11: -0.0042 | G11: 0.0169 | H11: -0.0274 | I11: 0 | J11: 0 | K11: 0 | L11: -0.037 | M11: 0.75 | N11: 0.1053 | O11: -0.0541 | P11: 0.1333 | Q11: 0 | R11: 0 | S11: 0 | T11: -1.3333 | U11: 2 | V11: 0 | Y11: collected by | AA11: Sauharda | AB11: Shrestha
A12: 8037300 | B12: CSAH 1 (Pioneer Trail) at Homeward Hills Rd | C12: 1st Calibration | D12: 46021 | E12: 0.35416667 | F12: -0.0045 | G12: 0.0163 | H12: -0.0211 | I12: 0.0198 | J12: -0.0645 | K12: 0 | L12: 0.0206 | M12: 0 | N12: 0.6667 | O12: -0.0387 | P12: 0 | Q12: 0 | R12: 0 | S12: 0.087 | T12: -0.1818 | U12: 0 | V12: 0 | Y12: Collected By | AA12: Sauharda Shrestha
A13: 8048500 | B13: CSAH 1 (Pioneer Trail) at Mitchell Rd | C13: 1st Calibration | D13: 46021 | E13: 0.63541667 | F13: -0.4615 | G13: 0.0382 | H13: -0.8667 | I13: -1.7333 | J13: -0.7879 | K13: -0.3529 | L13: 0.1159 | M13: -2 | N13: -0.2857 | O13: -0.8829 | P13: -2 | Q13: -2 | R13: -1.4286 | S13: -2 | T13: -2 | U13: -0.6667 | V13: -0.4 | Y13: Collected By: Sauharda Meher Shrestha
A14: 8052000 | B14: CSAH 1 (Pioneer Trail) at Staring Lake Parkway | C14: 1st Calibration | D14: 46022 | E14: 0.35416667 | F14: 0.0923 | G14: 0.08 | H14: 0.1091 | I14: 0 | J14: 0 | K14: 0 | L14: 0.0541 | M14: 0 | N14: 0 | O14: 0.1176 | P14: 0 | Q14: 0 | R14: 0 | S14: 0 | T14: 0 | U14: 0 | V14: 0 | Y14: Collected By: | AA14: Sauharda Meher Shrestha
A15: 8015500 | B15: CSAH 10 (Bass Lake Rd) at Boone Ave | C15: 1st Calibration | D15: 45295 | E15: off-peak | F15: -0.028809704 | G15: -0.0039138943 | H15: -0.02006689 | I15: -0.12903226 | J15: -0.017291066 | K15: -0.028169014 | L15: 0.015544041 | M15: -0.078212291 | N15: -0.024691358 | O15: -0.026200873 | P15: 0.015503876 | Q15: -0.4 | R15: -0.7008547 | S15: 0.45 | T15: -0.068965517 | U15: 0 | V15: 0
A16: 8025600 | B16: CSAH 10 (Bass Lake Rd) at CSAH 152 (Brooklyn Blvd) - Master Controller | C16: 1st Calibration | D16: 46035 | E16: 0.35416667 | F16: -0.0131 | G16: 0.0144 | H16: -0.0826 | I16: 0 | J16: 0.0062 | K16: -0.1053 | L16: 0.026 | M16: -0.0465 | N16: -0.1818 | O16: -0.0625 | P16: -0.087 | Q16: 0.2069 | R16: -0.0597 | S16: 0.0952 | T16: -0.0364 | U16: 0 | V16: 0.1176 | Y16: Collected By: | AA16: Sauharda Shrestha | AB16: Sauharda Shrestha
A17: 8043800 | B17: CSAH 10 (Bass Lake Rd) at International Pkwy / Gettysburg Ave | C17: 1st | D17: 45314 | E17: AM | F17: -0.043234588 | G17: -0.047125353 | H17: ? | I17: -0.076923077 | J17: 0.047619048 | K17: -0.035714286 | L17: -0.030696576 | M17: -0.19607843 | N17: ? | O17: ? | P17: ? | Q17: -0.15384615 | R17: 1.4285714 | S17: -0.22222222 | T17: 0 | U17: 0 | V17: 0.0625
A18: 8013100 | B18: CSAH 10 (Bass Lake Rd) at Jersey Ave | C18: 1st | D18: 45357 | E18: AM | F18: -0.156691 | G18: -0.071047957 | H18: -0.30747532 | I18: -0.19444444 | J18: 0.052631579 | K18: 0.12903226 | L18: -0.094194962 | M18: -0.013245033 | N18: -0.09929078 | O18: -0.3470483 | P18: -1.1111111 | Q18: 0.085106383 | R18: -1 | S18: -0.66666667 | T18: 0 | U18: 0.086956522 | V18: 0.044444444
A19: 8038800 | B19: CSAH 10 (Bass Lake Rd) at Nathan Ln | C19: 1st Calibration | D19: 45845 | E19: 0.32291667 | F19: -0.0926 | G19: -0.0182 | H19: -0.1472 | I19: -0.1639 | J19: -0.4828 | K19: 0 | L19: -0.0165 | M19: -0.0541 | N19: -0.0625 | O19: -0.0777 | P19: -0.3652 | Q19: 0 | R19: 0 | S19: -0.2041 | T19: -0.6667 | U19: 2 | V19: 0 | Y19: Collected By: | AA19: Sauharda Shrestha
A20: 8021000 | B20: CSAH 10 (Bass Lake Rd) at Regent Ave | C20: 1st Calibration | D20: 46034 | E20: 0.625 | F20: -0.7354 | G20: -0.2353 | H20: -1.2621 | I20: 0 | J20: -0.5882 | K20: -0.1538 | L20: -0.2408 | M20: 0 | N20: 0 | O20: -1.2621 | P20: 0 | Q20: 0 | R20: 0 | S20: 0 | T20: -0.6667 | U20: 0 | V20: -0.5714 | Y20: Collected By: | AA20: Sauharda Shrestha
A21: 8029100 | B21: CSAH 10 (Bass Lake Rd) at Sherburne Ave | C21: 1st Calibration | D21: 46034 | E21: 0.64583333 | F21: -0.4701 | G21: -0.6627 | H21: -0.1963 | I21: -0.2143 | J21: 0.25 | K21: -0.7826 | L21: -0.6667 | M21: 0 | N21: -0.2439 | O21: -0.1916 | P21: 0 | Q21: -1.3846 | R21: 0 | S21: 0.1463 | T21: 0.1538 | U21: 2 | V21: 0 | Y21: Collected By: | AA21: Sauharda Shrestha
A22: 8013500 | B22: CSAH 10 (Bass Lake Rd) at Shingle Creek Pkwy | C22: 1st Calibration | D22: 45320 | E22: off-peak | F22: 0.0088345226 | G22: 0.047407407 | H22: -0.044806517 | I22: 0.064516129 | J22: 0.0036429872 | K22: 0.19704433 | L22: -0.019889503 | M22: 0.051282051 | N22: -0.016260163 | O22: -0.039113429 | P22: -0.13043478 | Q22: -1.4285714 | R22: 0.75 | S22: 0.051282051 | T22: -0.88607595 | U22: 0.72340426 | V22: 0.010638298
A23: 8031600 | B23: CSAH 10 (Bass Lake Rd) at Sycamore Ln / Prudential Bldg - Master Controller | C23: 1st Calibration | D23: 46028 | E23: off-peak | F23: 0.0132 | G23: 0.0541 | H23: -0.0102 | I23: 0.1935 | J23: -0.084 | K23: -0.1639 | L23: 0.0941 | M23: 0.2857 | N23: 0 | O23: -0.0364 | P23: 0.1429 | Q23: 0.2857 | R23: -0.1333 | S23: 2 | T23: -0.125 | U23: 0 | V23: -0.0741 | Y23: Collected By: | AA23: Sauharda Shrestha
A24: 8052700 | B24: CSAH 10 (Bass Lake Rd) at Vicksburg Ln | C24: 1st Calibration | D24: 46036 | E24: 0.48958333 | F24: -0.0592 | G24: -0.2364 | H24: 0.0441 | I24: 0.0759 | J24: 0 | K24: 0 | L24: -0.4052 | M24: 0.2857 | N24: -0.1176 | O24: 0.0592 | P24: 0.1667 | Q24: 0.1538 | R24: 0.125 | S24: 0 | T24: 0 | U24: 0 | V24: 0 | Y24: Collected By: | AA24: Sauharda Shrestha
A25: 8005200 | B25: CSAH 10 (Bass Lake Rd) at Xerxes Ave N | C25: 1st Calibration | D25: 45322 | E25: off-peak | F25: -0.032454361 | G25: -0.015174507 | H25: -0.059405941 | I25: -0.024242424 | J25: -0.014492754 | K25: 1.3009709 | L25: -1.4551971 | M25: -0.084507042 | N25: -0.028169014 | O25: -0.15172414 | P25: 0.50847458 | Q25: -0.625 | R25: 0.077922078 | S25: 0 | T25: -0.66666667 | U25: 0.0097560976 | V25: -0.030769231
A26: 8024100 | B26: CSAH 10 (Bass Lake Rd) at Zachary Ln BACKHAUL | C26: 1st Calibration | D26: 46030 | E26: AM | F26: 0.0577 | G26: 0.0641 | H26: 0.1484 | I26: -0.1654 | J26: 0 | K26: 0.6667 | L26: 0.0496 | M26: 0.1754 | N26: -0.1333 | O26: 0.1818 | P26: 0 | Q26: -0.0952 | R26: -2 | S26: -0.1493 | T26: 0 | U26: 0 | V26: 0 | Y26: Collected By: | AA26: Sauharda Shrestha
A27: 8056000 | B27: CSAH 10 (County Road 10) at CSAH 116 (Fletcher Ln) | C27: 1st Calibration | D27: 46031 | E27: AM | F27: -0.0334 | G27: 0.016 | H27: -0.1765 | I27: 0.1935 | J27: -0.1654 | K27: 0 | L27: 0.1463 | M27: -0.3 | N27: -0.1538 | O27: 0 | P27: -0.7692 | Q27: 0.25 | R27: 0.1875 | S27: 0.1538 | T27: 0 | U27: -0.0935 | V27: -2 | Y27: Collected By | AA27: Sauharda Shrestha
A28: 8040000 | B28: CSAH 101 (Central Ave) at 14th Ave N - Master Controller | C28: NA | D28: NA | E28: NA
A29: 8035100 | B29: CSAH 101 (Central Ave) at Wayzata Blvd - Master Controller | C29: NA | D29: NA | E29: NA
A30: 8049100 | B30: CSAH 101 (County Rd 101) at Hutchins Dr | C30: NA | D30: NA | E30: NA
A31: 8049200 | B31: CSAH 101 (County Rd 101) at Seven Hi Drive (Cub Foods) | C31: NA | D31: NA | E31: NA
A32: 8054500 | B32: CSAH 101 (County Road 101) at Medina Rd BACKHAUL | C32: NA | D32: NA | E32: NA
A33: 8056300 | B33: CSAH 101 (County Road 101) at Ridgewood Rd | C33: NA | D33: NA | E33: NA
A34: 8046600 | B34: CSAH 101 at Lake Street Extension | C34: NA | D34: NA | E34: NA
A35: 8008600 | B35: CSAH 102 (Douglas Dr) at 36th Ave N | C35: NA | D35: NA | E35: NA
A36: 8017900 | B36: CSAH 102 (Douglas Dr) at 47th Ave N | C36: NA | D36: NA | E36: NA
A37: 8010300 | B37: CSAH 103 (West Broadway) at Candlewood Dr | C37: NA | D37: NA | E37: NA
A38: 8024500 | B38: CSAH 103 (West Broadway) at CSAH 130 / CSAH 152 (Brooklyn Blvd) - Master Controller | C38: 1st | D38: 45321 | E38: AM | F38: 0.0135318 | G38: 0.0099009901 | H38: 0.026557712 | I38: -0.014925373 | J38: 0.022116904 | K38: -0.067114094 | L38: 0.029363785 | M38: 0 | N38: -0.014184397 | O38: 0.272 | P38: -2 | Q38: 0 | R38: 0.23280423 | S38: -0.97959184 | T38: 0 | U38: 0.53023256 | V38: -2
A39: 8037100 | B39: CSAH 103 (West Broadway) at Dragon Star Supermarket/Rainbow Foods Driveway | C39: NA | D39: NA | E39: NA
A40: 9010810 | B40: CSAH 103 (West Broadway) at Oak Grove Pkwy | C40: NA | D40: NA | E40: NA
...

Sheet Baseline
A1: ID | B1: Intersection | C1: IP | D1: Date | E1: Time of Day | F1: Total | G1: EB Total | H1: WB Total | I1: NB Total | J1: SB Total | K1: EBL | L1: EBT | M1: EBR | N1: WBL | O1: WBT | P1: WBR | Q1: NBL | R1: NBT | S1: NBR | T1: SBL | U1: SBT | V1: SBR
A2: 8059100 | B2: CR 101 (Brockton Ln) at Dayton Parkway | C2: 192.168.136.9 | D2: 45839 | E2: 0.625 | F2: -0.0073 | G2: 0 | H2: 0.0146 | I2: 0.0396 | J2: -0.0667 | K2: 0 | L2: 0 | M2: 0 | N2: 0.0328 | O2: 0 | P2: 0 | Q2: 0.1538 | R2: 0.0225 | S2: 0.04 | T2: -0.1573 | U2: 0 | V2: 2 | X2: Collected By: | Z2: Sauharda Shrestha
A3: 8008400 | B3: CSAH 1 (Old Shakopee Rd) at CSAH 17 (France Ave) | C3: 192.168.36.76 | D3: 45118 | E3: AM | F3: 0.015607581 | G3: 0.0062695925 | H3: 0.049689441 | I3: -0.019417476 | J3: -0.013071895 | K3: -0.025974026 | L3: 0.034482759 | M3: -0.4 | N3: -0.85714286 | O3: 0.18791946 | P3: -2 | Q3: -0.14285714 | R3: 0.42622951 | S3: -1.7142857 | T3: 0 | U3: 0.11320755 | V3: -0.14285714
A4: 8018400 | B4: CSAH 1 (Old Shakopee Rd) at CSAH 34 (Normandale Blvd) | C4: 192.168.47.201 | D4: 45379 | E4: off-peak | F4: -0.28043306 | G4: -0.26849315 | H4: -0.0076394194 | I4: -0.36866359 | J4: -0.85616438 | K4: -1.1873016 | L4: 0.10760668 | M4: -2 | N4: -0.46464646 | O4: 0.20540541 | P4: -1.92 | Q4: -0.068965517 | R4: -0.018518519 | S4: -2 | T4: -0.073170732 | U4: -0.02247191 | V4: -2
A5: 8044600 | B5: CSAH 1 (Old Shakopee Rd) at Nesbitt Ave | C5: 192.168.47.169 | D5: 45114 | E5: AM | F5: -0.41691843 | G5: -0.32727273 | H5: -0.54961832 | I5: -0.55555556 | J5: -0.11764706 | K5: 0 | L5: -0.30463576 | M5: -2 | N5: 0 | O5: -0.62608696 | P5: 0 | Q5: -0.33333333 | R5: 1 | S5: -2 | T5: 0.22222222 | U5: 0 | V5: -0.28571429
A6: 8022400 | B6: CSAH 1 (Old Shakopee Rd) at Xerxes Ave S | C6: 192.168.47.233 | D6: 45350 | E6: off-peak | F6: -0.31742243 | G6: -0.45673759 | H6: -0.14439324 | I6: -0.43902439 | J6: -0.10810811 | K6: 0.92307692 | L6: -0.28183362 | M6: -2 | N6: 0 | O6: -0.15088283 | P6: 0 | Q6: -0.475 | R6: -0.4 | S6: -0.32258065 | T6: -1 | U6: 0.044444444 | V6: 0.11764706
A7: 8052100 | B7: CSAH 1 (Pioneer Trail) at Bennett Place | C7: 192.168.122.233 | D7: 45772 | E7: 0.32291667 | F7: -0.0335 | G7: -0.0651 | H7: -0.0241 | I7: 0.0351 | J7: 0 | K7: 0 | L7: -0.069 | M7: 0 | N7: 0 | O7: -0.026 | P7: 0 | Q7: 0 | R7: 0.6667 | S7: 0 | T7: 0 | U7: 0 | V7: 0 | X7: Collected by: | Z7: Sauharda Shrestha
A8: 8037200 | B8: CSAH 1 (Pioneer Trail) at CSAH 4 (Eden Prairie Rd) | C8: 192.168.122.105 | D8: 45391 | E8: off-peak | F8: -0.019 | G8: 0.2052506 | H8: -0.056338028 | I8: -0.171875 | J8: -0.079136691 | K8: 0.35294118 | L8: 0.008097166 | M8: 0.79245283 | N8: 0.5 | O8: -0.20689655 | P8: 0.097777778 | Q8: -0.057142857 | R8: -0.02955665 | S8: -2 | T8: -0.1 | U8: -0.053571429 | V8: -0.090909091 | X8: Collected by: | Z8: Sauharda Shrestha
A9: 8057300 | B9: CSAH 1 (Pioneer Trail) at CSAH 61 (Flying Cloud Dr) | C9: 192.168.114.41 | D9: 45119 | E9: AM | F9: 0.0053191489 | G9: -0.023529412 | H9: 0.036630037 | I9: -0.025316456 | J9: 0.013245033 | K9: -0.039215686 | L9: 0.088495575 | M9: -2 | N9: 0 | O9: 0.054054054 | P9: 0.025316456 | Q9: 0 | R9: 0.15602837 | S9: -2 | T9: -0.046511628 | U9: 0.71604938 | V9: -2 | X9: Collected by: | Z9: Sauharda Shrestha
A10: 8051400 | B10: CSAH 1 (Pioneer Trail) at Dell Rd | C10: 192.168.122.73 | D10: 45776 | E10: 0.34375 | F10: -0.0596 | G10: 0.0606 | H10: -0.0417 | I10: -0.3429 | J10: -0.0282 | K10: 0.0339 | L10: 0.0822 | M10: 0 | N10: -0.2222 | O10: -0.0465 | P10: 0 | Q10: 0 | R10: -0.0377 | S10: -1.6923 | T10: -0.069 | U10: 0 | V10: 0 | X10: Collected by: | Z10: Sauharda Shrestha | AA10: Shrestha
A11: 8037400 | B11: CSAH 1 (Pioneer Trail) at Franlo Rd | C11: 192.168.123.9 | D11: 45777 | E11: 0.32291667 | F11: -0.2278 | G11: -0.2353 | H11: -0.2353 | I11: -0.3158 | J11: 0 | K11: -0.2857 | L11: -0.2394 | M11: 0 | N11: -0.1818 | O11: -0.2081 | P11: -1.3333 | Q11: -0.6667 | R11: 0.2857 | S11: 0 | T11: -2 | U11: 1.1429 | V11: 0 | X11: Collected By: | Z11: Sauharda Shrestha
A12: 8037300 | B12: CSAH 1 (Pioneer Trail) at Homeward Hills Rd | C12: 192.168.122.201 | D12: 45778 | E12: 0.32291667 | F12: -0.0159 | G12: 0.0153 | H12: -0.013 | I12: -0.0556 | J12: -0.1 | K12: 0 | L12: 0.0185 | M12: 0 | N12: -0.3529 | O12: 0.063 | P12: -0.3784 | Q12: -0.0328 | R12: 0.0952 | S12: -0.2439 | T12: -0.087 | U12: 0 | V12: -2 | X12: Collected by: | Z12: Sauharda Shrestha
A13: 8048500 | B13: CSAH 1 (Pioneer Trail) at Mitchell Rd | C13: 192.168.122.137 | D13: 45812 | E13: 0.63541667 | F13: -0.011 | G13: -0.0426 | H13: 0.0164 | I13: 0.0952 | J13: -0.0465 | K13: -1.4286 | L13: 0 | M13: 0 | N13: 0 | O13: 0.0174 | P13: 0 | Q13: 0 | R13: 0.2222 | S13: 0 | T13: 0 | U13: -0.1538 | V13: 0 | X13: Collected by: | Z13: Sauharda Shrestha
A14: 8052000 | B14: CSAH 1 (Pioneer Trail) at Staring Lake Parkway | C14: 192.168.122.169 | D14: 45812 | E14: 0.35416667 | F14: -0.0706 | G14: -0.0578 | H14: 0.0134 | I14: -2 | J14: -0.75 | K14: 0 | L14: -0.0621 | M14: 0 | N14: 0 | O14: 0.0142 | P14: 0 | Q14: 0 | R14: 0 | S14: -2 | T14: 0.2222 | U14: 0 | V14: -2 | X14: Collected by: | Z14: Sauharda Shrestha
A15: 8015500 | B15: CSAH 10 (Bass Lake Rd) at Boone Ave | C15: 192.168.45.233 | D15: 45119 | E15: off-peak | F15: -0.04485555 | G15: -0.40837696 | H15: -0.041335453 | I15: 0 | J15: 0 | K15: -0.4 | L15: -0.41577061 | M15: 0 | N15: 0 | O15: -0.042553191 | P15: 0 | Q15: 0 | R15: 0 | S15: 0 | T15: 0 | U15: 0 | V15: 0
A16: 8025600 | B16: CSAH 10 (Bass Lake Rd) at CSAH 152 (Brooklyn Blvd) - Master Controller | C16: 192.168.23.76 | D16: 45117 | E16: AM | F16: -0.036697248 | G16: -0.06557377 | H16: -0.15652174 | I16: 0.054644809 | J16: -0.034188034 | K16: 0 | L16: -0.14084507 | M16: 0.074074074 | N16: 0 | O16: -0.11764706 | P16: -0.24390244 | Q16: 0.068965517 | R16: 0 | S16: 0.33333333 | T16: -0.074074074 | U16: -0.5625 | V16: 1.3076923
A17: 8043800 | B17: CSAH 10 (Bass Lake Rd) at International Pkwy / Gettysburg Ave | C17: 192.168.45.201 | D17: 45098 | E17: AM | F17: -0.38228056 | G17: 0 | H17: 0 | I17: -0.13682093 | J17: -0.097794823 | K17: -0.095238095 | L17: 0.076923077 | M17: 0.15384615 | N17: -0.1025641 | O17: 0.14285714 | P17: 0 | Q17: -0.18181818 | R17: -0.12446352 | S17: -0.35294118 | T17: -0.035087719 | U17: -0.11510791 | V17: -0.021052632
A18: 8013100 | B18: CSAH 10 (Bass Lake Rd) at Jersey Ave | C18: 192.168.46.73 | D18: 45098 | E18: AM | F18: -0.17454689 | G18: 0.020477816 | H18: -0.020876827 | I18: 0.086021505 | J18: 0 | K18: -0.095238095 | L18: 0.025862069 | M18: 0.01980198 | N18: 0.1 | O18: -0.024691358 | P18: -0.11764706 | Q18: 0.097560976 | R18: 0.125 | S18: 0.055555556 | T18: -0.083333333 | U18: 0.046511628 | V18: 0.10526316
A19: 8038800 | B19: CSAH 10 (Bass Lake Rd) at Nathan Ln | C19: 192.168.45.169 | D19: 45110 | E19: PM | F19: -0.20026702 | G19: -0.26022305 | H19: 0.0054200542 | I19: -0.84444444 | J19: -0.28571429 | K19: 0 | L19: -0.25327511 | M19: -0.375 | N19: -0.08 | O19: 0.051948052 | P19: -0.90909091 | Q19: 0 | R19: -0.4 | S19: -1.3454545 | T19: -0.18181818 | U19: 0.4 | V19: -1.2
A20: 8021000 | B20: CSAH 10 (Bass Lake Rd) at Regent Ave | C20: 192.168.46.137 | D20: 45104 | E20: PM | F20: -0.37333333 | G20: -0.25149701 | H20: -0.58823529 | I20: 0 | J20: 0 | K20: -0.5 | L20: -0.23899371 | M20: 0 | N20: 0 | O20: -0.58823529 | P20: 0 | Q20: 0 | R20: 0 | S20: 0 | T20: 0 | U20: 0 | V20: 0
A21: 8029100 | B21: CSAH 10 (Bass Lake Rd) at Sherburne Ave | C21: 192.168.46.105 | D21: 45125 | E21: PM | F21: -0.034766697 | G21: -0.028747433 | H21: -0.0076335878 | I21: -0.37037037 | J21: 0 | K21: 0 | L21: -0.027027027 | M21: -0.086956522 | N21: -0.025316456 | O21: -0.0093023256 | P21: 0.13333333 | Q21: 0 | R21: -0.66666667 | S21: -0.41860465 | T21: -0.10526316 | U21: 0.4 | V21: 0
A22: 8013500 | B22: CSAH 10 (Bass Lake Rd) at Shingle Creek Pkwy | C22: 192.168.46.233 | D22: 45112 | E22: off-peak | F22: 0.25917215 | G22: -0.015174507 | H22: -0.059405941 | I22: -0.024242424 | J22: -0.014492754 | K22: 1.3009709 | L22: -1.4551971 | M22: -0.084507042 | N22: -0.028169014 | O22: -0.15172414 | P22: 0.50847458 | Q22: -0.625 | R22: 0.077922078 | S22: 0 | T22: -0.66666667 | U22: 0.0097560976 | V22: -0.030769231
A23: 8031600 | B23: CSAH 10 (Bass Lake Rd) at Sycamore Ln / Prudential Bldg - Master Controller | C23: 192.168.45.41 | D23: 45348 | E23: off-peak | F23: -0.13111727 | G23: -0.14925373 | H23: -0.15115005 | I23: 0 | J23: -0.041884817 | K23: -0.31304348 | L23: -0.091338583 | M23: 0 | N23: 0 | O23: -0.049382716 | P23: -0.95145631 | Q23: 0 | R23: 0 | S23: 0 | T23: -0.14285714 | U23: 0 | V23: -0.013422819
A24: 8052700 | B24: CSAH 10 (Bass Lake Rd) at Vicksburg Ln | C24: 192.168.27.233 | D24: 45355 | E24: off-peak | F24: -0.062145366 | G24: -0.1321267 | H24: -0.029069767 | I24: -0.019310345 | J24: -0.060606061 | K24: -0.96875 | L24: -0.025641026 | M24: -0.010152284 | N24: -0.10126582 | O24: -0.014285714 | P24: -0.081632653 | Q24: -0.19672131 | R24: 0.67741935 | S24: -2 | T24: -0.23076923 | U24: 0.75714286 | V24: -1.963964
A25: 8005200 | B25: CSAH 10 (Bass Lake Rd) at Xerxes Ave N | C25: 192.168.46.169 | D25: 45098 | E25: off-peak | F25: 0.0144 | G25: 0.012711864 | H25: 0.021024967 | I25: -0.04214876 | J25: -0.20801317 | K25: -0.16197183 | L25: 0.088693957 | M25: -0.25471698 | N25: -0.096385542 | O25: 0.044491525 | P25: -0.004040404 | Q25: -0.072202166 | R25: 0.031210986 | S25: -0.42424242 | T25: -0.16235632 | U25: 0.013812155 | V25: -0.68656716
A26: 8024100 | B26: CSAH 10 (Bass Lake Rd) at Zachary Ln BACKHAUL | C26: 192.168.45.137 | D26: 45110 | E26: AM | F26: -0.31635389 | G26: -0.50632911 | H26: -0.18439716 | I26: -0.18181818 | J26: 0 | K26: -0.66666667 | L26: -0.58646617 | M26: 0 | N26: -0.31578947 | O26: -0.091743119 | P26: -0.76923077 | Q26: -1.3846154 | R26: 1.2 | S26: -2 | T26: 0 | U26: 0 | V26: 0
... A28: 8040000 | B28: CSAH 101 (Central Ave) at 14th Ave N - Master Controller | C28: 192.168.20.76 | D28: 45350 | E28: off-peak | F28: -0.24768946 | G28: -0.064516129 | H28: -1.0447761 | I28: -0.12639405 | J28: -0.3552 | K28: -0.090909091 | L28: -0.46153846 | M28: 0.029850746 | N28: -2 | O28: -0.4 | P28: -0.8 | Q28: -0.44897959 | R28: -0.10584958 | S28: -0.1 | T28: 0 | U28: -0.39160839 | V28: 0.064516129
A29: 8035100 | B29: CSAH 101 (Central Ave) at Wayzata Blvd - Master Controller | C29: 192.168.130.9 | D29: 45813 | E29: 0.625 | F29: 0.0222 | G29: 0.0285 | H29: 0.0406 | I29: -0.3529 | J29: 0.0064 | K29: 0 | L29: 0.0386 | M29: 0 | N29: 0 | O29: 0.0659 | P29: 0 | Q29: 0 | R29: 0 | S29: -0.8572 | T29: -0.0964 | U29: 0.5885 | V29: 0.0615 | X29: Collected by: | Z29: Sauharda | AA29: Shrestha
A30: 8049100 | B30: CSAH 101 (County Rd 101) at Hutchins Dr | C30: 192.168.131.9 | D30: 45817 | E30: 0.52083333 | F30: -0.0885 | G30: -0.1235 | H30: 0.069 | I30: -0.2205 | J30: 0.0197 | K30: -0.4762 | L30: 0.6667 | M30: 0.2222 | N30: 0 | O30: 0.1176 | P30: 0 | Q30: 0 | R30: -0.2578 | S30: 0 | T30: 0.1429 | U30: 0.0083 | V30: 0 | X30: Collected By: | Z30: Sauharda | AA30: Shrestha
A31: 8049200 | B31: CSAH 101 (County Rd 101) at Seven Hi Drive (Cub Foods) | C31: 192.168.130.233 | D31: 45323 | E31: off-peak | F31: -0.091240344 | G31: -0.036036036 | H31: -0.011363636 | I31: -0.6391545 | J31: -0.040114613 | K31: -0.027548209 | L31: -0.24615385 | M31: -0.0071513707 | N31: 0.019417476 | O31: -0.24113475 | P31: 0 | Q31: -0.6119403 | R31: -0.15122873 | S31: -1.9898219 | T31: -0.010152284 | U31: -0.050655022 | V31: -0.038834951
A32: 8054500 | B32: CSAH 101 (County Road 101) at Medina Rd BACKHAUL | C32: 192.168.20.11 | D32: 45295 | E32: PM | F32: 0.047722343 | G32: 0.052631579 | H32: 0.090909091 | I32: 0.014814815 | J32: 0.058252427 | K32: 0.20689655 | L32: -0.57142857 | M32: 0 | N32: 0 | O32: -0.25 | P32: 0.30769231 | Q32: 0.66666667 | R32: 0 | S32: 0 | T32: 0.054054054 | U32: 0.060606061 | V32: 0.054054054
A33: 8056300 | B33: CSAH 101 (County Road 101) at Ridgewood Rd | C33: 192.168.130.201 | D33: 45357 | E33: off-peak | F33: -0.40416048 | G33: 0.028985507 | H33: NA | I33: -0.2891933 | J33: -0.64972777 | K33: -0.033898305 | L33: 2 | M33: 0.051282051 | N33: NA | O33: NA | P33: NA | Q33: 0 | R33: -0.31301483 | S33: NA | T33: NA | U33: -0.77637131 | V33: 0.12987013
A34: 8046600 | B34: CSAH 101 at Lake Street Extension | C34: 192.168.130.169 | D34: 45113 | E34: AM | F34: -0.28824834 | G34: -0.28571429 | H34: -0.036363636 | I34: -0.5025641 | J34: -0.1443299 | K34: 0 | L34: 0 | M34: -0.66666667 | N34: -0.28571429 | O34: 0.4 | P34: 0.18181818 | Q34: -0.28571429 | R34: -0.62420382 | S34: 0.064516129 | T34: 0 | U34: -0.175 | V34: 0
A35: 8008600 | B35: CSAH 102 (Douglas Dr) at 36th Ave N | C35: 192.168.15.73 | D35: 45100 | E35: AM | F35: -0.1797 | G35: -0.1031 | H35: -0.08 | I35: -0.8276 | J35: -0.1408 | K35: -0.5455 | L35: 0 | M35: -2 | N35: -0.4444 | O35: 0.1579 | P35: -2 | Q35: -0.6667 | R35: 0 | S35: -1.68 | T35: 0 | U35: 0 | V35: -0.5882
A36: 8017900 | B36: CSAH 102 (Douglas Dr) at 47th Ave N | C36: 192.168.15.41 | D36: 45103 | E36: AM | F36: -0.28793774 | G36: -0.35294118 | H36: 0 | I36: -0.31372549 | J36: -0.32142857 | K36: -0.5 | L36: 0.66666667 | M36: -2 | N36: 0 | O36: 0 | P36: 0 | Q36: 0.4 | R36: -0.29787234 | S36: -2 | T36: -0.66666667 | U36: -0.26415094 | V36: -2
A37: 8010300 | B37: CSAH 103 (West Broadway) at Candlewood Dr | C37: 192.168.135.233 | D37: 45378 | E37: off-peak | F37: -0.45208486 | G37: -0.34782609 | H37: NA | I37: -0.26512968 | J37: -0.6919105 | K37: -0.93333333 | L37: 2 | M37: 0.13333333 | N37: NA | O37: NA | P37: NA | Q37: NA | R37: -0.26086957 | S37: -0.32 | T37: 0.44444444 | U37: -0.73309609 | V37: 2
A38: 8024500 | B38: CSAH 103 (West Broadway) at CSAH 130 / CSAH 152 (Brooklyn Blvd) - Master Controller | C38: 192.168.33.172 | D38: 45106 | E38: AM | F38: 0.016973533 | G38: 0.27722251 | H38: 0.059551431 | I38: 3.0065789 | J38: 0.045253863 | K38: 0.84006462 | L38: 0.0048504446 | M38: 0.022222222 | N38: 0.20295203 | O38: 0.035714286 | P38: -0.079365079 | Q38: -1 | R38: 16.666667 | S38: -0.036585366 | T38: -0.47619048 | U38: 0.36627907 | V38: 0.044515103 | X38: Collected by: | Z38: Sauharda Shrestha
A39: 8037100 | B39: CSAH 103 (West Broadway) at Dragon Star Supermarket/Rainbow Foods Driveway | C39: 192.168.51.73 | D39: 45817 | E39: 0.66666667 | F39: -0.1156 | G39: -0.4691 | H39: -0.5556 | I39: -0.0597 | J39: -0.0361 | K39: -0.1053 | L39: 0 | M39: -2 | N39: -0.3333 | O39: 0 | P39: -0.8 | Q39: 0 | R39: -0.0645 | S39: -0.0645 | T39: 0 | U39: -0.0175 | V39: -0.1714 | X39: Collected By: | Z39: Sauharda Shrestha | AA39: Shrestha
A40: 9010810 | B40: CSAH 103 (West Broadway) at Oak Grove Pkwy | C40: 192.168.15.233 | D40: 45818 | E40: 0.625 | F40: 0.0615 | G40: 0 | H40: 0 | I40: 0.1053 | J40: 0.0324 | K40: 0 | L40: 0 | M40: 0 | N40: 0.3784 | O40: -2 | P40: -0.0444 | Q40: -2 | R40: 0.0168 | S40: 0.314 | T40: 0.0625 | U40: 0.0165 | V40: 0 | X40: Collected By: | Z40: Sauharda Shrestha
A41: 8057750 | B41: CSAH 103 (Winnetka Ave N) at 109th Ave N | C41: 192.168.15.201 | D41: 45118 | E41: AM | F41: -0.07960199 | G41: -0.057142857 | H41: 0.03030303 | I41: 0 | J41: -0.33707865 | K41: 0 | L41: -0.028169014 | M41: -0.18181818 | N41: -0.10526316 | O41: 0.17021277 | P41: -0.52631579 | Q41: -0.10526316 | R41: 0.037735849 | S41: 0 | T41: -0.54545455 | U41: 0 | V41: -0.85714286
...

Sheet 1st Calibration Comparisons
A1: ID | B1: Intersection | C1: Calibration # | D1: Date | E1: Time of Day | F1: Total | G1: EB Total | H1: WB Total | I1: NB Total | J1: SB Total | K1: EBL | L1: EBT | M1: EBR | N1: WBL | O1: WBT | P1: WBR | Q1: NBL | R1: NBT | S1: NBR | T1: SBL | U1: SBT | V1: SBR
A2: 8001000 | B2: CSAH 5 (Minnetonka Blvd) at Texas Ave | C2: 1st | D2: 45329 | E2: PM | F2: -0.042352941 | G2: -0.050847458 | H2: -0.038834951 | I2: -0.044692737 | J2: -0.025531915 | K2: 0.021978022 | L2: 0.034013605 | M2: -2 | N2: -0.026315789 | O2: 0.088888889 | P2: -2 | Q2: -0.057142857 | R2: -0.14173228 | S2: 0.020408163 | T2: 0.12765957 | U2: 0.074074074 | V2: -0.41509434
A3: 8001100 | B3: CSAH 5 (Minnetonka Blvd) at Louisiana Ave | C3: 1st | D3: 45329 | E3: PM | F3: -0.068170426 | G3: -0.0056338028 | H3: -0.054968288 | I3: -0.068796069 | J3: -0.13562232 | K3: -0.26737968 | L3: 0.050251256 | M3: 0.048780488 | N3: -0.23076923 | O3: 0.020618557 | P3: -0.16666667 | Q3: -0.21468927 | R3: -0.010968921 | S3: -0.13333333 | T3: -0.3059867 | U3: -0.012958963 | V3: -0.055776892
